git config --global user.email 1114891937@qq.com
git config --global user.name WeiXia
git checkout main
git reset --hard origin/main
git pull
conda activate django
python /home/xw/backend/manage.py runserver 0.0.0.0:8000
(base) xw@VM-20-3-ubuntu:~/backend$ git config --global user.email 1114891937@qq
.com
(base) xw@VM-20-3-ubuntu:~/backend$ git config --global user.name WeiXia
(base) xw@VM-20-3-ubuntu:~/backend$ git checkout main
Already on 'main'
Your branch is up to date with 'origin/main'.
(base) xw@VM-20-3-ubuntu:~/backend$ git reset --hard origin/main
HEAD is now at 3239795 utils
(base) xw@VM-20-3-ubuntu:~/backend$ git pull
remote: Enumerating objects: 37, done.
remote: Counting objects: 100% (32/32), done.
remote: Compressing objects: 100% (6/6), done.
remote: Total 19 (delta 13), reused 19 (delta 13), pack-reused 0
Unpacking objects: 100% (19/19), 3.52 KiB | 1.17 MiB/s, done.
From https://github.com/summer-semester-backend/backend
   3239795..c7becf9  main       -> origin/main
Updating 3239795..c7becf9
Fast-forward
 backend/__pycache__/settings.cpython-39.pyc | Bin 3049 -> 3049 bytes
 user/__pycache__/urls.cpython-39.pyc        | Bin 230 -> 356 bytes
 user/__pycache__/views.cpython-39.pyc       | Bin 373 -> 2069 bytes
 user/urls.py                                |   4 ++
 user/views.py                               |  64 ++++++++++++++++++++++++++--
 5 files changed, 65 insertions(+), 3 deletions(-)
(base) xw@VM-20-3-ubuntu:~/backend$ conda activate django
(django) xw@VM-20-3-ubuntu:~/backend$ python /home/xw/backend/manage.py runserve
r 0.0.0.0:8000
Watching for file changes with StatReloader
Performing system checks...

Exception in thread django-main-thread:
Traceback (most recent call last):
  File "/home/xw/miniconda3/envs/django/lib/python3.8/threading.py", line 932, i
n _bootstrap_inner
    self.run()
  File "/home/xw/miniconda3/envs/django/lib/python3.8/threading.py", line 870, i
n run
    self._target(*self._args, **self._kwargs)
  File "/home/xw/miniconda3/envs/django/lib/python3.8/site-packages/django/utils
/autoreload.py", line 64, in wrapper
    fn(*args, **kwargs)
  File "/home/xw/miniconda3/envs/django/lib/python3.8/site-packages/django/core/
management/commands/runserver.py", line 134, in inner_run
    self.check(display_num_errors=True)
  File "/home/xw/miniconda3/envs/django/lib/python3.8/site-packages/django/core/
management/base.py", line 487, in check
    all_issues = checks.run_checks(
  File "/home/xw/miniconda3/envs/django/lib/python3.8/site-packages/django/core/
checks/registry.py", line 88, in run_checks
    new_errors = check(app_configs=app_configs, databases=databases)
  File "/home/xw/miniconda3/envs/django/lib/python3.8/site-packages/django/core/
checks/urls.py", line 14, in check_url_config
    return check_resolver(resolver)
  File "/home/xw/miniconda3/envs/django/lib/python3.8/site-packages/django/core/
checks/urls.py", line 24, in check_resolver
    return check_method()
  File "/home/xw/miniconda3/envs/django/lib/python3.8/site-packages/django/urls/
resolvers.py", line 480, in check
    for pattern in self.url_patterns:
  File "/home/xw/miniconda3/envs/django/lib/python3.8/site-packages/django/utils
/functional.py", line 49, in __get__
    res = instance.__dict__[self.name] = self.func(instance)
  File "/home/xw/miniconda3/envs/django/lib/python3.8/site-packages/django/urls/
resolvers.py", line 696, in url_patterns
    patterns = getattr(self.urlconf_module, "urlpatterns", self.urlconf_module)
  File "/home/xw/miniconda3/envs/django/lib/python3.8/site-packages/django/utils
/functional.py", line 49, in __get__
    res = instance.__dict__[self.name] = self.func(instance)
  File "/home/xw/miniconda3/envs/django/lib/python3.8/site-packages/django/urls/
resolvers.py", line 689, in urlconf_module
    return import_module(self.urlconf_name)
  File "/home/xw/miniconda3/envs/django/lib/python3.8/importlib/__init__.py", li
ne 127, in import_module
    return _bootstrap._gcd_import(name[level:], package, level)
  File "<frozen importlib._bootstrap>", line 1014, in _gcd_import
  File "<frozen importlib._bootstrap>", line 991, in _find_and_load
  File "<frozen importlib._bootstrap>", line 975, in _find_and_load_unlocked
  File "<frozen importlib._bootstrap>", line 671, in _load_unlocked
  File "<frozen importlib._bootstrap_external>", line 843, in exec_module
  File "<frozen importlib._bootstrap>", line 219, in _call_with_frames_removed
  File "/home/xw/backend/backend/urls.py", line 21, in <module>
    path('api/user/', include(('user.urls', 'user')))
  File "/home/xw/miniconda3/envs/django/lib/python3.8/site-packages/django/urls/
conf.py", line 38, in include
    urlconf_module = import_module(urlconf_module)
  File "/home/xw/miniconda3/envs/django/lib/python3.8/importlib/__init__.py", li
ne 127, in import_module
    return _bootstrap._gcd_import(name[level:], package, level)
  File "<frozen importlib._bootstrap>", line 1014, in _gcd_import
  File "<frozen importlib._bootstrap>", line 991, in _find_and_load
  File "<frozen importlib._bootstrap>", line 975, in _find_and_load_unlocked
  File "<frozen importlib._bootstrap>", line 671, in _load_unlocked
  File "<frozen importlib._bootstrap_external>", line 843, in exec_module
  File "<frozen importlib._bootstrap>", line 219, in _call_with_frames_removed
  File "/home/xw/backend/user/urls.py", line 2, in <module>
    from .views import *
  File "/home/xw/backend/user/views.py", line 61, in <module>
    from backend.utils.utils import *
ModuleNotFoundError: No module named 'backend.utils'

